<?xml version="1.0"?>
<robot xmlns:xacro="http://www.ros.org/wiki/xacro">

	<xacro:property name="PI" value="3.1415926535897931"/>

<!-- ROBOT LINKS -->
    <link name="base_link">
		<visual>
			<origin xyz="0 0 0" rpy="0 0 0"/>
			<geometry>
				<mesh filename="package://indy7_description/meshes/stl/Indy7_0.stl"/>
			</geometry>
		</visual>
		<collision>
			<origin xyz="0 0 0" rpy="0 0 0"/>
			<geometry>
				<cylinder length="0.06" radius="0.102"/>
			</geometry>
		</collision>

    <inertial>
        <mass value="1.59306955"/>
        <origin xyz="0 0 0" rpy="0 0 0"/>
        <inertia ixx="0.00572623" ixy="0.00000251" ixz="-0.00011380" iyy="0.00558959" iyz="-0.00000014" izz="0.00966674" />
    </inertial>
    </link>

    <link name="link1">
		<visual>
			<origin xyz="0 0 0" rpy="0 0 0"/>
			<geometry>
				<mesh filename="package://indy7_description/meshes/stl/Indy7_1.stl"/>
			</geometry>
		</visual>
		<collision>
			<origin xyz="0 0 0.111" rpy="0 0 0"/>
			<geometry>
				<cylinder length="0.222" radius="0.075"/>
			</geometry>
		</collision>
		<collision>
			<origin xyz="0 -0.0545 0.222" rpy="${PI/2} 0 0"/>
			<geometry>
				<cylinder length="0.109" radius="0.075"/>
			</geometry>
		</collision>
    <inertial>
        <mass value="1.59306955"/>
        <origin xyz="0 0 0" rpy="0 0 0"/>
        <inertia ixx="0.15418559" ixy="-0.00000235" ixz="0.00001739" iyy="0.12937017" iyz="-0.04854267" izz="0.05964415" />
    </inertial>
    </link>

    <link name="link2">
		<visual>
			<origin xyz="0 0 0" rpy="0 0 0"/>
			<geometry>
				<mesh filename="package://indy7_description/meshes/stl/Indy7_2.stl"/>
			</geometry>
		</visual>
		<collision>
			<origin xyz="-0.225 0 0.09" rpy="${PI/2} 0 -${PI/2}"/>
			<geometry>
				<cylinder length="0.450" radius="0.063"/>
			</geometry>
		</collision>
		<collision>
			<origin xyz="0 0 0.045" rpy="0 0 0"/>
			<geometry>
				<cylinder length="0.09" radius="0.075"/>
			</geometry>
		</collision>
		<collision>
			<origin xyz="-0.45 0 0.02975 " rpy="0 0 0"/>
			<geometry>
				<cylinder length="0.1205" radius="0.045"/>
			</geometry>
		</collision>
    <inertial>
        <mass value="0.18"/>
        <origin xyz="0 0 0" rpy="0 0 0"/>
        <inertia ixx="0.29356980" ixy="-0.00000040" ixz="0.00001441" iyy="0.25088420" iyz="0.03727972" izz="0.03620519" />
    </inertial>
    </link>


    <link name="link3">
		<visual>
			<origin xyz="0 0 0" rpy="0 0 0"/>
			<geometry>
				<mesh filename="package://indy7_description/meshes/stl/Indy7_3.stl"/>
			</geometry>
		</visual>
		<collision>
			<origin xyz="-0.1335 0 -0.075" rpy="${PI/2} 0 -${PI/2}"/>
			<geometry>
				<cylinder length="0.267" radius="0.045"/>
			</geometry>
		</collision>
		<collision>
			<origin xyz="0 0 -0.0375" rpy="0 0 0"/>
			<geometry>
				<cylinder length="0.075" radius="0.045"/>
			</geometry>
		</collision>
    <inertial>
        <mass value="0.18"/>
        <origin xyz="0 0 0.11" rpy="0 0 0"/>
        <inertia ixx="0.03424593" ixy="0.00000149" ixz="0.00000724" iyy="0.03406024" iyz="0.00186009" izz="0.00450477" />
    </inertial>
    </link>

    <link name="link4">
		<visual>
			<origin xyz="0 0 0" rpy="0 0 0"/>
			<geometry>
				<mesh filename="package://indy7_description/meshes/stl/Indy7_4.stl"/>
			</geometry>
		</visual>
		<collision>
			<origin xyz="0 -0.057 0.083" rpy="${PI/2} 0 0"/>
			<geometry>
				<cylinder length="0.114" radius="0.045"/>
			</geometry>
		</collision>
		<collision>
			<origin xyz="0 -0.057 0.083" rpy="${PI/2} 0 0"/>
			<geometry>
				<cylinder length="0.114" radius="0.045"/>
			</geometry>
		</collision>
		<collision>
			<origin xyz="0 0 0.0415" rpy="0 0 0"/>
			<geometry>
				<cylinder length="0.083" radius="0.045"/>
			</geometry>
		</collision>
    <inertial>
        <mass value="0.18"/>
        <origin xyz="0 0 0" rpy="0 0 0"/>
        <inertia ixx="0.00670405" ixy="0.00000375" ixz="0.00000150" iyy="0.00670405" iyz="-0.00127967" izz="0.00617624" />
    </inertial>
    </link>

    <link name="link5">
		<visual>
			<origin xyz="0 0 0" rpy="0 0 0"/>
			<geometry>
				<mesh filename="package://indy7_description/meshes/stl/Indy7_5.stl"/>
			</geometry>
		</visual>
		<collision>
			<origin xyz="-0.084 0 0.069" rpy="${PI/2} 0 -${PI/2}"/>
			<geometry>
				<cylinder length="0.168" radius="0.045"/>
			</geometry>
		</collision>
		<collision>
			<origin xyz="-0 0 0.0345" rpy="0 0 0"/>
			<geometry>
				<cylinder length="0.069" radius="0.045"/>
			</geometry>
		</collision>
    <inertial>
        <mass value="0.18"/>
        <origin xyz="-0.1875 0 0.062" rpy="0 0 0"/>
        <inertia ixx="0.00994891" ixy="0.00000014" ixz="0.00000321" iyy="0.00978189" iyz="-0.00093546" izz="0.00271492" />
    </inertial>
    </link>

    <link name="link6">
		<visual>
			<origin xyz="0 0 0" rpy="0 0 0"/>
			<geometry>
				<mesh filename="package://indy7_description/meshes/stl/Indy7_6.stl"/>
			</geometry>
		</visual>
		<collision>
			<origin xyz="0 0 0.03" rpy="0 0 0"/>
			<geometry>
				<cylinder length="0.06" radius="0.045"/>
			</geometry>
		</collision>
    <inertial>
        <mass value="0.18"/>
        <origin xyz="0 0 0.0125" rpy="0 0 0"/>
        <inertia ixx="0.00043534" ixy="0.00000013" ixz="-0.00000002" iyy="0.00044549" iyz="0.00000051" izz="0.00059634" />
    </inertial>    
    </link>

<!-- ROBOT JOINTS -->

    

    <joint name="base_link__link_01" type="revolute">
    	<parent link="base_link"/>
		<child link="link1"/>
		<origin xyz="0 0 0.03000000" rpy="0 0 0"/>
		<axis xyz="0 0 1"/>
        <limit effort="1000.0" lower="-2" upper="2" velocity="0.5" />
    </joint>
    
    <joint name="link1_link2" type="revolute">
      	<parent link="link1"/>
		<child link="link2"/>
		<origin xyz="0 -0.10900000 0.22200000" rpy="${PI/2} ${PI/2} 0"/>
	    <axis xyz="0 0 1"/>
        <limit effort="1000.0" lower="-2" upper="2" velocity="0.5" />
    </joint>


    <joint name="link2_link3" type="revolute">
   		<parent link="link2"/>
		<child link="link3"/>
		<origin xyz="-0.45000000 +0.00000000 -0.03050000" rpy="0 0 0"/>
		<axis xyz="0 0 1"/>
      <limit effort="1000.0" lower="-3" upper="3" velocity="0.5" />
    </joint>


    <joint name="link3_link4" type="revolute">
    	<parent link="link3"/>
		<child link="link4"/>
		<origin xyz="-0.26700000 +0.00000000 -0.07500000" rpy="-${PI/2} 0 ${PI/2}"/>
		<axis xyz="0 0 1"/>
      <limit effort="1000.0" lower="-3" upper="3" velocity="0.5" />
    </joint>

<!-- 
need offset on x and y axis (link 3 and 4 are not exactly on point)
-->
    <joint name="link4_link5" type="revolute">
		<parent link="link4"/>
		<child link="link5"/>
		<origin xyz="+0.00000000 -0.11400000 +0.08300000" rpy="${PI/2} ${PI/2} 0"/>
		<axis xyz="0 0 1"/>
        <limit effort="1000.0" lower="-3" upper="3" velocity="0.5" />
    </joint>

    <joint name="link5_link6" type="revolute">
    	<parent link="link5"/>
		<child link="link6"/>
		<origin xyz="-0.16800000 +0.00000000 +0.06900000" rpy="-${PI/2} 0 ${PI/2}"/>
		<axis xyz="0 0 1"/>
        <limit effort="1000.0" lower="-3.2" upper="3.2" velocity="0.5" />
    </joint>

</robot>
